INFO:root:Бот стартовал
INFO:apscheduler.scheduler:Scheduler started
INFO:root:Вызван /start
INFO:root:user_text
ERROR:telegram.ext.dispatcher:No error handlers are registered, logging exception.
Traceback (most recent call last):
  File "/Library/Frameworks/Python.framework/Versions/3.8/lib/python3.8/site-packages/telegram/ext/dispatcher.py", line 555, in process_update
    handler.handle_update(update, self, check, context)
  File "/Library/Frameworks/Python.framework/Versions/3.8/lib/python3.8/site-packages/telegram/ext/handler.py", line 198, in handle_update
    return self.callback(update, context)
TypeError: define_planet_position() takes 1 positional argument but 2 were given
ERROR:telegram.ext.dispatcher:No error handlers are registered, logging exception.
Traceback (most recent call last):
  File "/Library/Frameworks/Python.framework/Versions/3.8/lib/python3.8/site-packages/telegram/ext/dispatcher.py", line 555, in process_update
    handler.handle_update(update, self, check, context)
  File "/Library/Frameworks/Python.framework/Versions/3.8/lib/python3.8/site-packages/telegram/ext/handler.py", line 198, in handle_update
    return self.callback(update, context)
TypeError: define_planet_position() takes 1 positional argument but 2 were given
ERROR:telegram.ext.dispatcher:No error handlers are registered, logging exception.
Traceback (most recent call last):
  File "/Library/Frameworks/Python.framework/Versions/3.8/lib/python3.8/site-packages/telegram/ext/dispatcher.py", line 555, in process_update
    handler.handle_update(update, self, check, context)
  File "/Library/Frameworks/Python.framework/Versions/3.8/lib/python3.8/site-packages/telegram/ext/handler.py", line 198, in handle_update
    return self.callback(update, context)
TypeError: define_planet_position() takes 1 positional argument but 2 were given
ERROR:telegram.ext.dispatcher:No error handlers are registered, logging exception.
Traceback (most recent call last):
  File "/Library/Frameworks/Python.framework/Versions/3.8/lib/python3.8/site-packages/telegram/ext/dispatcher.py", line 555, in process_update
    handler.handle_update(update, self, check, context)
  File "/Library/Frameworks/Python.framework/Versions/3.8/lib/python3.8/site-packages/telegram/ext/handler.py", line 198, in handle_update
    return self.callback(update, context)
TypeError: define_planet_position() takes 1 positional argument but 2 were given
ERROR:telegram.ext.updater:Error while getting Updates: Conflict: terminated by other getUpdates request; make sure that only one bot instance is running
ERROR:telegram.ext.dispatcher:No error handlers are registered, logging exception.
Traceback (most recent call last):
  File "/Library/Frameworks/Python.framework/Versions/3.8/lib/python3.8/site-packages/telegram/ext/updater.py", line 646, in _network_loop_retry
    if not action_cb():
  File "/Library/Frameworks/Python.framework/Versions/3.8/lib/python3.8/site-packages/telegram/ext/updater.py", line 597, in polling_action_cb
    updates = self.bot.get_updates(
  File "/Library/Frameworks/Python.framework/Versions/3.8/lib/python3.8/site-packages/telegram/ext/extbot.py", line 222, in get_updates
    updates = super().get_updates(
  File "/Library/Frameworks/Python.framework/Versions/3.8/lib/python3.8/site-packages/telegram/bot.py", line 130, in decorator
    result = func(*args, **kwargs)
  File "/Library/Frameworks/Python.framework/Versions/3.8/lib/python3.8/site-packages/telegram/bot.py", line 2861, in get_updates
    self._post(
  File "/Library/Frameworks/Python.framework/Versions/3.8/lib/python3.8/site-packages/telegram/bot.py", line 295, in _post
    return self.request.post(
  File "/Library/Frameworks/Python.framework/Versions/3.8/lib/python3.8/site-packages/telegram/utils/request.py", line 356, in post
    result = self._request_wrapper(
  File "/Library/Frameworks/Python.framework/Versions/3.8/lib/python3.8/site-packages/telegram/utils/request.py", line 283, in _request_wrapper
    raise Conflict(message)
telegram.error.Conflict: Conflict: terminated by other getUpdates request; make sure that only one bot instance is running
ERROR:telegram.ext.updater:Error while getting Updates: Conflict: terminated by other getUpdates request; make sure that only one bot instance is running
ERROR:telegram.ext.dispatcher:No error handlers are registered, logging exception.
Traceback (most recent call last):
  File "/Library/Frameworks/Python.framework/Versions/3.8/lib/python3.8/site-packages/telegram/ext/updater.py", line 646, in _network_loop_retry
    if not action_cb():
  File "/Library/Frameworks/Python.framework/Versions/3.8/lib/python3.8/site-packages/telegram/ext/updater.py", line 597, in polling_action_cb
    updates = self.bot.get_updates(
  File "/Library/Frameworks/Python.framework/Versions/3.8/lib/python3.8/site-packages/telegram/ext/extbot.py", line 222, in get_updates
    updates = super().get_updates(
  File "/Library/Frameworks/Python.framework/Versions/3.8/lib/python3.8/site-packages/telegram/bot.py", line 130, in decorator
    result = func(*args, **kwargs)
  File "/Library/Frameworks/Python.framework/Versions/3.8/lib/python3.8/site-packages/telegram/bot.py", line 2861, in get_updates
    self._post(
  File "/Library/Frameworks/Python.framework/Versions/3.8/lib/python3.8/site-packages/telegram/bot.py", line 295, in _post
    return self.request.post(
  File "/Library/Frameworks/Python.framework/Versions/3.8/lib/python3.8/site-packages/telegram/utils/request.py", line 356, in post
    result = self._request_wrapper(
  File "/Library/Frameworks/Python.framework/Versions/3.8/lib/python3.8/site-packages/telegram/utils/request.py", line 283, in _request_wrapper
    raise Conflict(message)
telegram.error.Conflict: Conflict: terminated by other getUpdates request; make sure that only one bot instance is running
ERROR:telegram.ext.dispatcher:No error handlers are registered, logging exception.
Traceback (most recent call last):
  File "/Library/Frameworks/Python.framework/Versions/3.8/lib/python3.8/site-packages/telegram/ext/dispatcher.py", line 555, in process_update
    handler.handle_update(update, self, check, context)
  File "/Library/Frameworks/Python.framework/Versions/3.8/lib/python3.8/site-packages/telegram/ext/handler.py", line 198, in handle_update
    return self.callback(update, context)
TypeError: define_planet_position() takes 1 positional argument but 2 were given
ERROR:telegram.ext.updater:Error while getting Updates: Conflict: terminated by other getUpdates request; make sure that only one bot instance is running
ERROR:telegram.ext.dispatcher:No error handlers are registered, logging exception.
Traceback (most recent call last):
  File "/Library/Frameworks/Python.framework/Versions/3.8/lib/python3.8/site-packages/telegram/ext/updater.py", line 646, in _network_loop_retry
    if not action_cb():
  File "/Library/Frameworks/Python.framework/Versions/3.8/lib/python3.8/site-packages/telegram/ext/updater.py", line 597, in polling_action_cb
    updates = self.bot.get_updates(
  File "/Library/Frameworks/Python.framework/Versions/3.8/lib/python3.8/site-packages/telegram/ext/extbot.py", line 222, in get_updates
    updates = super().get_updates(
  File "/Library/Frameworks/Python.framework/Versions/3.8/lib/python3.8/site-packages/telegram/bot.py", line 130, in decorator
    result = func(*args, **kwargs)
  File "/Library/Frameworks/Python.framework/Versions/3.8/lib/python3.8/site-packages/telegram/bot.py", line 2861, in get_updates
    self._post(
  File "/Library/Frameworks/Python.framework/Versions/3.8/lib/python3.8/site-packages/telegram/bot.py", line 295, in _post
    return self.request.post(
  File "/Library/Frameworks/Python.framework/Versions/3.8/lib/python3.8/site-packages/telegram/utils/request.py", line 356, in post
    result = self._request_wrapper(
  File "/Library/Frameworks/Python.framework/Versions/3.8/lib/python3.8/site-packages/telegram/utils/request.py", line 283, in _request_wrapper
    raise Conflict(message)
telegram.error.Conflict: Conflict: terminated by other getUpdates request; make sure that only one bot instance is running
INFO:root:Бот стартовал
INFO:apscheduler.scheduler:Scheduler started
INFO:root:Вызван /start
ERROR:telegram.ext.dispatcher:No error handlers are registered, logging exception.
Traceback (most recent call last):
  File "/Library/Frameworks/Python.framework/Versions/3.8/lib/python3.8/site-packages/telegram/ext/dispatcher.py", line 555, in process_update
    handler.handle_update(update, self, check, context)
  File "/Library/Frameworks/Python.framework/Versions/3.8/lib/python3.8/site-packages/telegram/ext/handler.py", line 198, in handle_update
    return self.callback(update, context)
TypeError: define_planet_position() takes 1 positional argument but 2 were given
INFO:telegram.ext.updater:Received signal 2 (SIGINT), stopping...
INFO:apscheduler.scheduler:Scheduler has been shut down
INFO:root:Бот стартовал
INFO:apscheduler.scheduler:Scheduler started
INFO:root:obtain_planet
ERROR:telegram.ext.dispatcher:No error handlers are registered, logging exception.
Traceback (most recent call last):
  File "/Library/Frameworks/Python.framework/Versions/3.8/lib/python3.8/site-packages/telegram/ext/dispatcher.py", line 555, in process_update
    handler.handle_update(update, self, check, context)
  File "/Library/Frameworks/Python.framework/Versions/3.8/lib/python3.8/site-packages/telegram/ext/handler.py", line 198, in handle_update
    return self.callback(update, context)
  File "ephem_bot.py", line 46, in define_planet_position
    planet_2_constellation = ephem.constellation(which_planet)
UnboundLocalError: local variable 'which_planet' referenced before assignment
INFO:root:obtain_planet
ERROR:telegram.ext.dispatcher:No error handlers are registered, logging exception.
Traceback (most recent call last):
  File "/Library/Frameworks/Python.framework/Versions/3.8/lib/python3.8/site-packages/telegram/ext/dispatcher.py", line 555, in process_update
    handler.handle_update(update, self, check, context)
  File "/Library/Frameworks/Python.framework/Versions/3.8/lib/python3.8/site-packages/telegram/ext/handler.py", line 198, in handle_update
    return self.callback(update, context)
  File "ephem_bot.py", line 46, in define_planet_position
    planet_2_constellation = ephem.constellation(which_planet)
UnboundLocalError: local variable 'which_planet' referenced before assignment
INFO:telegram.ext.updater:Received signal 2 (SIGINT), stopping...
INFO:apscheduler.scheduler:Scheduler has been shut down
WARNING:telegram.ext.updater:Exiting immediately!
INFO:root:Бот стартовал
INFO:apscheduler.scheduler:Scheduler started
INFO:root:['/planet', 'Mars']
ERROR:telegram.ext.dispatcher:No error handlers are registered, logging exception.
Traceback (most recent call last):
  File "/Library/Frameworks/Python.framework/Versions/3.8/lib/python3.8/site-packages/telegram/ext/dispatcher.py", line 555, in process_update
    handler.handle_update(update, self, check, context)
  File "/Library/Frameworks/Python.framework/Versions/3.8/lib/python3.8/site-packages/telegram/ext/handler.py", line 198, in handle_update
    return self.callback(update, context)
  File "ephem_bot.py", line 46, in define_planet_position
    planet_2_constellation = ephem.constellation(which_planet)
UnboundLocalError: local variable 'which_planet' referenced before assignment
INFO:telegram.ext.updater:Received signal 2 (SIGINT), stopping...
INFO:apscheduler.scheduler:Scheduler has been shut down
WARNING:telegram.ext.updater:Exiting immediately!
INFO:root:Бот стартовал
INFO:apscheduler.scheduler:Scheduler started
INFO:root:['/planet', 'Mars']
INFO:root:['/planet', 'Pluto']
ERROR:telegram.ext.dispatcher:No error handlers are registered, logging exception.
Traceback (most recent call last):
  File "/Library/Frameworks/Python.framework/Versions/3.8/lib/python3.8/site-packages/telegram/ext/dispatcher.py", line 555, in process_update
    handler.handle_update(update, self, check, context)
  File "/Library/Frameworks/Python.framework/Versions/3.8/lib/python3.8/site-packages/telegram/ext/handler.py", line 198, in handle_update
    return self.callback(update, context)
  File "ephem_bot.py", line 20, in define_planet_position
    obtain_planet = update.message.text.split()
AttributeError: 'NoneType' object has no attribute 'text'
ERROR:telegram.ext.dispatcher:No error handlers are registered, logging exception.
Traceback (most recent call last):
  File "/Library/Frameworks/Python.framework/Versions/3.8/lib/python3.8/site-packages/telegram/ext/dispatcher.py", line 555, in process_update
    handler.handle_update(update, self, check, context)
  File "/Library/Frameworks/Python.framework/Versions/3.8/lib/python3.8/site-packages/telegram/ext/handler.py", line 198, in handle_update
    return self.callback(update, context)
  File "ephem_bot.py", line 20, in define_planet_position
    obtain_planet = update.message.text.split()
AttributeError: 'NoneType' object has no attribute 'text'
ERROR:telegram.ext.dispatcher:No error handlers are registered, logging exception.
Traceback (most recent call last):
  File "/Library/Frameworks/Python.framework/Versions/3.8/lib/python3.8/site-packages/telegram/ext/dispatcher.py", line 555, in process_update
    handler.handle_update(update, self, check, context)
  File "/Library/Frameworks/Python.framework/Versions/3.8/lib/python3.8/site-packages/telegram/ext/handler.py", line 198, in handle_update
    return self.callback(update, context)
  File "ephem_bot.py", line 20, in define_planet_position
    obtain_planet = update.message.text.split()
AttributeError: 'NoneType' object has no attribute 'text'
INFO:root:['/planet', 'fgfg']
ERROR:telegram.ext.dispatcher:No error handlers are registered, logging exception.
Traceback (most recent call last):
  File "/Library/Frameworks/Python.framework/Versions/3.8/lib/python3.8/site-packages/telegram/ext/dispatcher.py", line 555, in process_update
    handler.handle_update(update, self, check, context)
  File "/Library/Frameworks/Python.framework/Versions/3.8/lib/python3.8/site-packages/telegram/ext/handler.py", line 198, in handle_update
    return self.callback(update, context)
  File "ephem_bot.py", line 46, in define_planet_position
    planet_2_constellation = ephem.constellation(which_planet)
UnboundLocalError: local variable 'which_planet' referenced before assignment
INFO:root:['/planet', 'Pikachu']
ERROR:telegram.ext.dispatcher:No error handlers are registered, logging exception.
Traceback (most recent call last):
  File "/Library/Frameworks/Python.framework/Versions/3.8/lib/python3.8/site-packages/telegram/ext/dispatcher.py", line 555, in process_update
    handler.handle_update(update, self, check, context)
  File "/Library/Frameworks/Python.framework/Versions/3.8/lib/python3.8/site-packages/telegram/ext/handler.py", line 198, in handle_update
    return self.callback(update, context)
  File "ephem_bot.py", line 46, in define_planet_position
    planet_2_constellation = ephem.constellation(which_planet)
UnboundLocalError: local variable 'which_planet' referenced before assignment
INFO:root:['/planet', 'Aldraan']
ERROR:telegram.ext.dispatcher:No error handlers are registered, logging exception.
Traceback (most recent call last):
  File "/Library/Frameworks/Python.framework/Versions/3.8/lib/python3.8/site-packages/telegram/ext/dispatcher.py", line 555, in process_update
    handler.handle_update(update, self, check, context)
  File "/Library/Frameworks/Python.framework/Versions/3.8/lib/python3.8/site-packages/telegram/ext/handler.py", line 198, in handle_update
    return self.callback(update, context)
  File "ephem_bot.py", line 46, in define_planet_position
    planet_2_constellation = ephem.constellation(which_planet)
UnboundLocalError: local variable 'which_planet' referenced before assignment
INFO:root:['/planet', 'Alderaan']
ERROR:telegram.ext.dispatcher:No error handlers are registered, logging exception.
Traceback (most recent call last):
  File "/Library/Frameworks/Python.framework/Versions/3.8/lib/python3.8/site-packages/telegram/ext/dispatcher.py", line 555, in process_update
    handler.handle_update(update, self, check, context)
  File "/Library/Frameworks/Python.framework/Versions/3.8/lib/python3.8/site-packages/telegram/ext/handler.py", line 198, in handle_update
    return self.callback(update, context)
  File "ephem_bot.py", line 46, in define_planet_position
    planet_2_constellation = ephem.constellation(which_planet)
UnboundLocalError: local variable 'which_planet' referenced before assignment
INFO:telegram.ext.updater:Received signal 2 (SIGINT), stopping...
INFO:apscheduler.scheduler:Scheduler has been shut down
WARNING:telegram.ext.updater:Exiting immediately!
INFO:root:Бот стартовал
INFO:apscheduler.scheduler:Scheduler started
INFO:root:['/planet', 'Alderaan']
ERROR:telegram.ext.dispatcher:No error handlers are registered, logging exception.
Traceback (most recent call last):
  File "/Library/Frameworks/Python.framework/Versions/3.8/lib/python3.8/site-packages/telegram/ext/dispatcher.py", line 555, in process_update
    handler.handle_update(update, self, check, context)
  File "/Library/Frameworks/Python.framework/Versions/3.8/lib/python3.8/site-packages/telegram/ext/handler.py", line 198, in handle_update
    return self.callback(update, context)
  File "ephem_bot.py", line 46, in define_planet_position
    planet_2_constellation = ephem.constellation(which_planet)
UnboundLocalError: local variable 'which_planet' referenced before assignment
INFO:telegram.ext.updater:Received signal 2 (SIGINT), stopping...
INFO:apscheduler.scheduler:Scheduler has been shut down
WARNING:telegram.ext.updater:Exiting immediately!
INFO:root:Бот стартовал
INFO:apscheduler.scheduler:Scheduler started
INFO:root:['/planet', 'Uranus']
INFO:root:['/planet']
ERROR:telegram.ext.dispatcher:No error handlers are registered, logging exception.
Traceback (most recent call last):
  File "/Library/Frameworks/Python.framework/Versions/3.8/lib/python3.8/site-packages/telegram/ext/dispatcher.py", line 555, in process_update
    handler.handle_update(update, self, check, context)
  File "/Library/Frameworks/Python.framework/Versions/3.8/lib/python3.8/site-packages/telegram/ext/handler.py", line 198, in handle_update
    return self.callback(update, context)
  File "ephem_bot.py", line 22, in define_planet_position
    if obtain_planet[1] == 'Mars':
IndexError: list index out of range
INFO:root:user_text
INFO:telegram.ext.updater:Received signal 2 (SIGINT), stopping...
INFO:apscheduler.scheduler:Scheduler has been shut down
WARNING:telegram.ext.updater:Exiting immediately!
INFO:root:Бот стартовал
INFO:apscheduler.scheduler:Scheduler started
INFO:root:['/planet']
ERROR:telegram.ext.dispatcher:No error handlers are registered, logging exception.
Traceback (most recent call last):
  File "/Library/Frameworks/Python.framework/Versions/3.8/lib/python3.8/site-packages/telegram/ext/dispatcher.py", line 555, in process_update
    handler.handle_update(update, self, check, context)
  File "/Library/Frameworks/Python.framework/Versions/3.8/lib/python3.8/site-packages/telegram/ext/handler.py", line 198, in handle_update
    return self.callback(update, context)
  File "ephem_bot.py", line 22, in define_planet_position
    if obtain_planet[1] == 'Mars':
IndexError: list index out of range
INFO:root:['/planet', 'Neptune']
INFO:telegram.ext.updater:Received signal 2 (SIGINT), stopping...
INFO:apscheduler.scheduler:Scheduler has been shut down
WARNING:telegram.ext.updater:Exiting immediately!
